
<?xml version="0.0" ?>
<robot name="">
	<link name="switch">
		<inertial>
			<origin rpy="0 0 0" xyz="0.00000 0.00000 0.00000"/>
			<mass value="7.85398"/>
			<inertia ixx="0.923301" ixy="0" ixz="0" iyy="0.764585" iyz="0" izz="0.168533"/>
		</inertial>
	</link>
	<link name="handle">
		<inertial>
			<origin rpy="0 0 0" xyz="0.00000 0.00000 -0.1"/>
			<mass value="2.43455"/>
			<inertia ixx="0.0022722467" ixy="0" ixz="0" iyy="0.0022722467" iyz="0" izz="0.000486911"/>
		</inertial>
		<visual>
			<origin rpy="0 0 0" xyz="0.00000 0.00000 -0.1"/>
			<geometry>
				<!-- Note that we use a cylinder here, not a capsule - ignoring spherical ends -->
				<cylinder length="0.1" radius="0.02"/>
			</geometry>
			<material name="mat_-1_0">
				<color rgba="0.23438 0.72656 0.32812 1.00000" />
			</material>
		</visual>
		<collision>
			<origin rpy="0 0 0" xyz="0.00000 0.00000 -0.1"/>
			<geometry>
				<cylinder length="0.1" radius="0.02"/>
			</geometry>
		</collision>
	</link>
	<joint name="handle_hinge" type="continuous">
		<parent link="switch"/>
		<child link="handle"/>
		<dynamics damping="1.0" friction="0.1"/>
		<origin xyz="0.00000 0.00000 0.5"/>
		<axis xyz="-1.0 0.00000 0.00000"/>
	</joint>
</robot>
